Workbook

Sheet Emp_List
A1: ID | B1: Name | C1: Department
A2: P0001 | B2: Abel Sherman | C2: Finance | E2: Row Labels | F2: Count of Name
A3: P0002 | B3: Ahmed Cortez | C3: Marketing | E3: Finance | F3: 28
A4: P0003 | B4: Ali Hernandez | C4: Sales | E4: HR | F4: 11
A5: P0004 | B5: Asher Workman | C5: Marketing | E5: IT | F5: 15
A6: P0005 | B6: Ashley Workman | C6: Operations | E6: Marketing | F6: 16
A7: P0006 | B7: Avye Kelly | C7: IT | E7: Operations | F7: 16
A8: P0007 | B8: Barbara Mcconnell | C8: IT | E8: Sales | F8: 14
A9: P0008 | B9: Barclay Romero | C9: Sales | E9: Grand Total | F9: 100
A10: P0009 | B10: Basia David | C10: Operations
A11: P0010 | B11: Basia Davidhall | C11: Finance
A12: P0011 | B12: Bevis Mcpherson | C12: Finance
A13: P0012 | B13: Brooke Odom | C13: Sales
A14: P0013 | B14: Bruce Daily | C14: Operations
A15: P0014 | B15: Bruce Day | C15: Marketing
A16: P0015 | B16: Callie Jefferson | C16: Operations
A17: P0016 | B17: Castor Whitney | C17: Finance
A18: P0017 | B18: Charity Gross | C18: HR
A19: P0018 | B19: Ciaran Becker | C19: Sales
A20: P0019 | B20: Cole Shelton | C20: Operations
A21: P0020 | B21: Cole Sheraton | C21: Finance
... A101: P0100 | B101: Zeph Gill | C101: Marketing

Sheet Training_List
A1: ID | B1: Program name | C1: Trainer | D1: Date | E1: Year Only | F1: Duration | G1: Capacity | H1: Cost
A2: T001 | B2: Basic Sales Skills | C2: Eu Dolor Egestas Inc. | D2: 42009 | E2: =TEXT(D2,"yyyy") -> 2015 | F2: 1 | G2: 10 | H2: 5000
A3: T002 | B3: Basic Project Management Methods | C3: Morbi Tristique Industries | D3: 42023 | E3: =TEXT(D3,"yyyy") -> 2015 | F3: 1 | G3: 5 | H3: 4000
A4: T003 | B4: Basic People Management Techniques | C4: Interdum Company | D4: 42034 | E4: =TEXT(D4,"yyyy") -> 2015 | F4: 1 | G4: 30 | H4: 2000
A5: T004 | B5: Basic People Management Skills | C5: Metus In Nec Foundation | D5: 42047 | E5: =TEXT(D5,"yyyy") -> 2015 | F5: 1 | G5: 25 | H5: 6000
A6: T005 | B6: Basic People Management Methods | C6: Lacus Pede Company | D6: 42074 | E6: =TEXT(D6,"yyyy") -> 2015 | F6: 1 | G6: 20 | H6: 7000
A7: T006 | B7: Basic IT Methods | C7: Quisque PC | D7: 42087 | E7: =TEXT(D7,"yyyy") -> 2015 | F7: 1 | G7: 5 | H7: 2000
A8: T007 | B8: Basic Business Skills | C8: Libero At Auctor Associates | D8: 42111 | E8: =TEXT(D8,"yyyy") -> 2015 | F8: 1 | G8: 25 | H8: 2000
A9: T008 | B9: Basic Advertising Techniques | C9: Nulla Eu Incorporated | D9: 42136 | E9: =TEXT(D9,"yyyy") -> 2015 | F9: 1 | G9: 15 | H9: 2000
A10: T009 | B10: Basic Advertising Skills | C10: Vivamus Industries | D10: 42156 | E10: =TEXT(D10,"yyyy") -> 2015 | F10: 1 | G10: 15 | H10: 3000
A11: T010 | B11: Basic Advertising Methods | C11: Eu Dolor Egestas Inc. | D11: 42180 | E11: =TEXT(D11,"yyyy") -> 2015 | F11: 1 | G11: 5 | H11: 7000
A12: T011 | B12: Advanced Sales Techniques | C12: Morbi Tristique Industries | D12: 42194 | E12: =TEXT(D12,"yyyy") -> 2015 | F12: 0.5 | G12: 20 | H12: 2000
A13: T012 | B13: Advanced Sales Methods | C13: Interdum Company | D13: 42213 | E13: =TEXT(D13,"yyyy") -> 2015 | F13: 0.5 | G13: 30 | H13: 5000
... A22: T021 | B22: Advanced Advertising Skills | C22: Interdum Company | D22: 42384 | E22: =TEXT(D22,"yyyy") -> 2016 | F22: 1 | G22: 15 | H22: 6000

Sheet Emp_Training_Tracker
A1: Final Status | B1: Person Name | C1: Program Name | D1: Status | E1: Feedback Rating
A2: OK | B2: Timon Armstrong | C2: Basic Project Management Methods | D2: Nominated | E2: 5 - Very happy | G2: Row Labels | H2: Count of Person Name
A3: OK | B3: Ahmed Cortez | C3: Advanced Advertising Skills | D3: Nominated | E3: Ratings Unavailable | G3: Advanced Advertising Skills | H3: 11
A4: OK | B4: Ivory Sloan | C4: Basic Sales Skills | D4: Nominated | E4: 1 - Disaster | G4: Advanced Business Methods | H4: 9
A5: OK | B5: Colleen Bryan | C5: Advanced IT Skills | D5: Nominated | E5: Ratings Unavailable | G5: Advanced Business Techniques | H5: 1
A6: OK | B6: Kenneth Gallagher | C6: Basic Advertising Methods | D6: Nominated | E6: 4 - Happy | G6: Advanced IT Skills | H6: 6
A7: OK | B7: Perry Schmidt | C7: Advanced People Management Skills | D7: Nominated | E7: 4 - Happy | G7: Advanced IT Techniques | H7: 6
A8: OK | B8: Edward Glenn | C8: Basic Project Management Methods | D8: Nominated | E8: 3 - Average | G8: Advanced People Management Methods | H8: 8
A9: OK | B9: Tiger Bauer | C9: Advanced Business Methods | D9: Nominated | E9: Ratings Unavailable | G9: Advanced People Management Skills | H9: 7
A10: OK | B10: Yoshio Pierce | C10: Advanced Advertising Skills | D10: Nominated | E10: Ratings Unavailable | G10: Advanced People Management Techniques | H10: 5
A11: OK | B11: Dorothy Pena | C11: Advanced IT Techniques | D11: Nominated | E11: Ratings Unavailable | G11: Advanced Project Management Skills | H11: 5
A12: Duplicate enrollment | B12: Cole Shelton | C12: Advanced Advertising Skills | D12: Nominated | E12: Ratings Unavailable | G12: Advanced Sales Methods | H12: 9
A13: OK | B13: Bevis Mcpherson | C13: Basic People Management Methods | D13: Nominated | E13: 1 - Disaster | G13: Advanced Sales Techniques | H13: 9
A14: OK | B14: Abel Sherman | C14: Advanced People Management Techniques | D14: Nominated | E14: 2 - Not happy | G14: Basic Advertising Methods | H14: 5
... A24: OK | B24: Charity Gross | C24: Advanced Business Methods | D24: Nominated | E24: Ratings Unavailable | G24: Grand Total | H24: 146
A25: OK | B25: Rashad Hobbs | C25: Advanced Advertising Skills | D25: Nominated | E25: Ratings Unavailable
A26: OK | B26: Kay Rios | C26: Advanced Sales Methods | D26: Nominated | E26: 5 - Very happy
A27: OK | B27: George Mcleod | C27: Advanced Sales Methods | D27: Nominated | E27: 2 - Not happy
A28: OK | B28: Quinlan Mcbride | C28: Basic Sales Skills | D28: Nominated | E28: 1 - Disaster | G28: NOTE:
A29: OK | B29: Lydia Wolfe | C29: Basic Business Skills | D29: Nominated | E29: 3 - Average | G29: 1. The original file has incomplete data like in Feedback Ratings column. I replaced the blank cells into "Unrated" so my analysis become meaningful.
A30: OK | B30: Basia David | C30: Basic Advertising Skills | D30: Nominated | E30: 1 - Disaster | G30: 2. From 150 items,4 entries were deleted because of duplicates.
A31: OK | B31: Jade Weber | C31: Advanced People Management Methods | D31: Nominated | E31: 4 - Happy | G31: 3. The final status column is excluded from the analysis as the training capacity versus the actual participants did not all match.
A32: OK | B32: Prescott Mcknight | C32: Basic IT Methods | D32: Nominated | E32: 2 - Not happy | G32: Please see Calculations tab for more info.
A33: OK | B33: Stone Pickett | C33: Advanced IT Skills | D33: Nominated | E33: Ratings Unavailable
A34: OK | B34: Kathleen Chan | C34: Basic Advertising Techniques | D34: Nominated | E34: 1 - Disaster
A35: OK | B35: Asher Workman | C35: Basic People Management Techniques | D35: Nominated | E35: 4 - Happy
A36: OK | B36: Demetria Wiley | C36: Advanced Sales Techniques | D36: Nominated | E36: 1 - Disaster
A37: OK | B37: Bruce Day | C37: Basic Advertising Techniques | D37: Nominated | E37: 3 - Average
A38: OK | B38: Noelani Snyder | C38: Advanced Sales Techniques | D38: Nominated | E38: 5 - Very happy
A39: OK | B39: Cole Shelton | C39: Advanced Business Methods | D39: Nominated | E39: Ratings Unavailable
A40: OK | B40: Charity Gross | C40: Basic People Management Skills | D40: Nominated | E40: 1 - Disaster
A41: OK | B41: Otto Burke | C41: Advanced IT Skills | D41: Nominated | E41: Ratings Unavailable
A42: OK | B42: Basia David | C42: Basic Advertising Skills | D42: Nominated | E42: 2 - Not happy
A43: Duplicate enrollment | B43: Kellie Ferrell | C43: Advanced IT Skills | D43: Nominated | E43: Ratings Unavailable
A44: OK | B44: Mira Perkins | C44: Basic Project Management Methods | D44: Nominated | E44: 3 - Average
... A147: OK | B147: Kieran Wilson | C147: Advanced People Management Techniques | D147: Nominated | E147: 5 - Very happy
A148: OK
A149: Duplicate enrollment
A150: OK
A151: OK

Sheet Reference
B2: Department | C2: Years
B3: Finance | C3: 2015
B4: HR | C4: 2016
B5: IT
B6: Marketing
B7: Operations
B8: Sales
B9: All

Sheet Calculations
E1: TRAINING INFO SUMMARY
E2: Training Name | F2: Training Capacity | G2: Actual Number of Participants (Employee per Program) | H2: Cost | I2: Year | J2: Ratings | Q2: Row Labels | R2: Sum of Actual Number of Participants | S2: Sum of Training Capacity
B3: Fiscal Year | C3: =Dashboard!$E$6 -> 2016 | J3: 1 - Disaster | K3: 2 - Not happy | L3: 3 - Average | M3: 4 - Happy | N3: 5 - Very happy | O3: Unrated | Q3: 2015 | R3: 126 | S3: 335 | U3: Training Name | V3: 1 - Disaster | W3: 2 - Not happy | X3: 3 - Average | Y3: 4 - Happy | Z3: 5 - Very happy | AA3: Unrated
B4: Department | C4: =Dashboard!$W$6 -> 0 | E4: Basic Sales Skills | F4: 10 | G4: =COUNTIF($G$40:$G$185,E4) -> 9 | H4: 5000 | I4: 2015 | J4: =COUNTIFS($L$40:$L$185,$J$3,$G$40:$G$185,E4) -> 2 | K4: =COUNTIFS($L$40:$L$185,$K$3,$G$40:$G$185,E4) -> 2 | L4: =COUNTIFS($L$40:$L$185,$L$3,$G$40:$G$185,E4) -> 3 | M4: =COUNTIFS($L$40:$L$185,$M$3,$G$40:$G$185,E4) -> 2 | N4: =COUNTIFS($L$40:$L$185,$N$3,$G$40:$G$185,E4) -> 0 | O4: =COUNTIFS($L$40:$L$185,$O$3,$G$40:$G$185,E4) -> 0 | Q4: 2016 | R4: 20 | S4: 45 | U4: Basic Sales Skills | V4: 2 | W4: 2 | X4: 3 | Y4: 2 | Z4: 0 | AA4: 0
B5: Training Cost | C5: =SUMIF($I$4:$I$24,C3,$H$4:$H$24) -> 9000 | E5: Basic Project Management Methods | F5: 5 | G5: =COUNTIF($G$40:$G$185,E5) -> 14 | H5: 4000 | I5: 2015 | J5: =COUNTIFS($L$40:$L$185,$J$3,$G$40:$G$185,E5) -> 3 | K5: =COUNTIFS($L$40:$L$185,$K$3,$G$40:$G$185,E5) -> 1 | L5: =COUNTIFS($L$40:$L$185,$L$3,$G$40:$G$185,E5) -> 4 | M5: =COUNTIFS($L$40:$L$185,$M$3,$G$40:$G$185,E5) -> 3 | N5: =COUNTIFS($L$40:$L$185,$N$3,$G$40:$G$185,E5) -> 3 | O5: =COUNTIFS($L$40:$L$185,$O$3,$G$40:$G$185,E5) -> 0 | Q5: Grand Total | R5: 146 | S5: 380 | U5: Basic Project Management Methods | V5: 3 | W5: 1 | X5: 4 | Y5: 3 | Z5: 3 | AA5: 0
B6: Total Participants | C6: =SUMIF($I$4:$I$24,$C$3,$G$4:$G$24) -> 20 | E6: Basic People Management Techniques | F6: 30 | G6: =COUNTIF($G$40:$G$185,E6) -> 4 | H6: 2000 | I6: 2015 | J6: =COUNTIFS($L$40:$L$185,$J$3,$G$40:$G$185,E6) -> 1 | K6: =COUNTIFS($L$40:$L$185,$K$3,$G$40:$G$185,E6) -> 0 | L6: =COUNTIFS($L$40:$L$185,$L$3,$G$40:$G$185,E6) -> 1 | M6: =COUNTIFS($L$40:$L$185,$M$3,$G$40:$G$185,E6) -> 2 | N6: =COUNTIFS($L$40:$L$185,$N$3,$G$40:$G$185,E6) -> 0 | O6: =COUNTIFS($L$40:$L$185,$O$3,$G$40:$G$185,E6) -> 0 | U6: Basic People Management Techniques | V6: 1 | W6: 0 | X6: 1 | Y6: 2 | Z6: 0 | AA6: 0
B7: Total Training Hours | C7: =SUMIF($K$40:$K$185,$C$3,$J$40:$J$185) -> 20 | E7: Basic People Management Skills | F7: 25 | G7: =COUNTIF($G$40:$G$185,E7) -> 6 | H7: 6000 | I7: 2015 | J7: =COUNTIFS($L$40:$L$185,$J$3,$G$40:$G$185,E7) -> 1 | K7: =COUNTIFS($L$40:$L$185,$K$3,$G$40:$G$185,E7) -> 1 | L7: =COUNTIFS($L$40:$L$185,$L$3,$G$40:$G$185,E7) -> 2 | M7: =COUNTIFS($L$40:$L$185,$M$3,$G$40:$G$185,E7) -> 1 | N7: =COUNTIFS($L$40:$L$185,$N$3,$G$40:$G$185,E7) -> 1 | O7: =COUNTIFS($L$40:$L$185,$O$3,$G$40:$G$185,E7) -> 0 | U7: Basic People Management Skills | V7: 1 | W7: 1 | X7: 2 | Y7: 1 | Z7: 1 | AA7: 0
B8: Actual Number of Participants | C8: =SUMIF($I$4:$I$24,$C$3,$G$4:$G$24) -> 20 | E8: Basic People Management Methods | F8: 20 | G8: =COUNTIF($G$40:$G$185,E8) -> 7 | H8: 7000 | I8: 2015 | J8: =COUNTIFS($L$40:$L$185,$J$3,$G$40:$G$185,E8) -> 2 | K8: =COUNTIFS($L$40:$L$185,$K$3,$G$40:$G$185,E8) -> 2 | L8: =COUNTIFS($L$40:$L$185,$L$3,$G$40:$G$185,E8) -> 0 | M8: =COUNTIFS($L$40:$L$185,$M$3,$G$40:$G$185,E8) -> 2 | N8: =COUNTIFS($L$40:$L$185,$N$3,$G$40:$G$185,E8) -> 1 | O8: =COUNTIFS($L$40:$L$185,$O$3,$G$40:$G$185,E8) -> 0 | U8: Basic People Management Methods | V8: 2 | W8: 2 | X8: 0 | Y8: 2 | Z8: 1 | AA8: 0
B9: Training Capacity | C9: =SUMIF($I$4:$I$24,$C$3,$F$4:$F$24) -> 45 | E9: Basic IT Methods | F9: 5 | G9: =COUNTIF($G$40:$G$185,E9) -> 4 | H9: 2000 | I9: 2015 | J9: =COUNTIFS($L$40:$L$185,$J$3,$G$40:$G$185,E9) -> 1 | K9: =COUNTIFS($L$40:$L$185,$K$3,$G$40:$G$185,E9) -> 1 | L9: =COUNTIFS($L$40:$L$185,$L$3,$G$40:$G$185,E9) -> 1 | M9: =COUNTIFS($L$40:$L$185,$M$3,$G$40:$G$185,E9) -> 0 | N9: =COUNTIFS($L$40:$L$185,$N$3,$G$40:$G$185,E9) -> 1 | O9: =COUNTIFS($L$40:$L$185,$O$3,$G$40:$G$185,E9) -> 0 | U9: Basic IT Methods | V9: 1 | W9: 1 | X9: 1 | Y9: 0 | Z9: 1 | AA9: 0
B10: Occupancy Rate | C10: =C8/C9 -> 0.44444444 | E10: Basic Business Skills | F10: 25 | G10: =COUNTIF($G$40:$G$185,E10) -> 2 | H10: 2000 | I10: 2015 | J10: =COUNTIFS($L$40:$L$185,$J$3,$G$40:$G$185,E10) -> 0 | K10: =COUNTIFS($L$40:$L$185,$K$3,$G$40:$G$185,E10) -> 0 | L10: =COUNTIFS($L$40:$L$185,$L$3,$G$40:$G$185,E10) -> 1 | M10: =COUNTIFS($L$40:$L$185,$M$3,$G$40:$G$185,E10) -> 1 | N10: =COUNTIFS($L$40:$L$185,$N$3,$G$40:$G$185,E10) -> 0 | O10: =COUNTIFS($L$40:$L$185,$O$3,$G$40:$G$185,E10) -> 0 | U10: Basic Business Skills | V10: 0 | W10: 0 | X10: 1 | Y10: 1 | Z10: 0 | AA10: 0
B11: Training Cost - % change | C11: =IF(C3=2015,0, IF(C3=2016,($C$13-$C$12)/$C$13,0)) -> 0.74285714 | E11: Basic Advertising Techniques | F11: 15 | G11: =COUNTIF($G$40:$G$185,E11) -> 10 | H11: 2000 | I11: 2015 | J11: =COUNTIFS($L$40:$L$185,$J$3,$G$40:$G$185,E11) -> 3 | K11: =COUNTIFS($L$40:$L$185,$K$3,$G$40:$G$185,E11) -> 2 | L11: =COUNTIFS($L$40:$L$185,$L$3,$G$40:$G$185,E11) -> 3 | M11: =COUNTIFS($L$40:$L$185,$M$3,$G$40:$G$185,E11) -> 0 | N11: =COUNTIFS($L$40:$L$185,$N$3,$G$40:$G$185,E11) -> 2 | O11: =COUNTIFS($L$40:$L$185,$O$3,$G$40:$G$185,E11) -> 0 | U11: Basic Advertising Techniques | V11: 3 | W11: 2 | X11: 3 | Y11: 0 | Z11: 2 | AA11: 0
B12: Training Cost - current year | C12: =C5 -> 9000 | E12: Basic Advertising Skills | F12: 15 | G12: =COUNTIF($G$40:$G$185,E12) -> 9 | H12: 3000 | I12: 2015 | J12: =COUNTIFS($L$40:$L$185,$J$3,$G$40:$G$185,E12) -> 4 | K12: =COUNTIFS($L$40:$L$185,$K$3,$G$40:$G$185,E12) -> 1 | L12: =COUNTIFS($L$40:$L$185,$L$3,$G$40:$G$185,E12) -> 1 | M12: =COUNTIFS($L$40:$L$185,$M$3,$G$40:$G$185,E12) -> 2 | N12: =COUNTIFS($L$40:$L$185,$N$3,$G$40:$G$185,E12) -> 1 | O12: =COUNTIFS($L$40:$L$185,$O$3,$G$40:$G$185,E12) -> 0 | U12: Basic Advertising Skills | V12: 4 | W12: 1 | X12: 1 | Y12: 2 | Z12: 1 | AA12: 0
B13: Training Cost - previous year | C13: 35000 | E13: Basic Advertising Methods | F13: 5 | G13: =COUNTIF($G$40:$G$185,E13) -> 5 | H13: 7000 | I13: 2015 | J13: =COUNTIFS($L$40:$L$185,$J$3,$G$40:$G$185,E13) -> 0 | K13: =COUNTIFS($L$40:$L$185,$K$3,$G$40:$G$185,E13) -> 1 | L13: =COUNTIFS($L$40:$L$185,$L$3,$G$40:$G$185,E13) -> 1 | M13: =COUNTIFS($L$40:$L$185,$M$3,$G$40:$G$185,E13) -> 2 | N13: =COUNTIFS($L$40:$L$185,$N$3,$G$40:$G$185,E13) -> 1 | O13: =COUNTIFS($L$40:$L$185,$O$3,$G$40:$G$185,E13) -> 0 | U13: Basic Advertising Methods | V13: 0 | W13: 1 | X13: 1 | Y13: 2 | Z13: 1 | AA13: 0
B14: Total Training Hours - % change | C14: =IF(C3=2015,0, IF(C3=2016,($C$16-$C$15)/$C$16,0)) -> 0.83333333 | E14: Advanced Sales Techniques | F14: 20 | G14: =COUNTIF($G$40:$G$185,E14) -> 9 | H14: 2000 | I14: 2015 | J14: =COUNTIFS($L$40:$L$185,$J$3,$G$40:$G$185,E14) -> 1 | K14: =COUNTIFS($L$40:$L$185,$K$3,$G$40:$G$185,E14) -> 0 | L14: =COUNTIFS($L$40:$L$185,$L$3,$G$40:$G$185,E14) -> 1 | M14: =COUNTIFS($L$40:$L$185,$M$3,$G$40:$G$185,E14) -> 2 | N14: =COUNTIFS($L$40:$L$185,$N$3,$G$40:$G$185,E14) -> 5 | O14: =COUNTIFS($L$40:$L$185,$O$3,$G$40:$G$185,E14) -> 0 | U14: Advanced Sales Techniques | V14: 1 | W14: 0 | X14: 1 | Y14: 2 | Z14: 5 | AA14: 0
B15: Total Training Hours - current year | C15: 20 | E15: Advanced Sales Methods | F15: 30 | G15: =COUNTIF($G$40:$G$185,E15) -> 9 | H15: 5000 | I15: 2015 | J15: =COUNTIFS($L$40:$L$185,$J$3,$G$40:$G$185,E15) -> 1 | K15: =COUNTIFS($L$40:$L$185,$K$3,$G$40:$G$185,E15) -> 1 | L15: =COUNTIFS($L$40:$L$185,$L$3,$G$40:$G$185,E15) -> 1 | M15: =COUNTIFS($L$40:$L$185,$M$3,$G$40:$G$185,E15) -> 2 | N15: =COUNTIFS($L$40:$L$185,$N$3,$G$40:$G$185,E15) -> 4 | O15: =COUNTIFS($L$40:$L$185,$O$3,$G$40:$G$185,E15) -> 0 | U15: Advanced Sales Methods | V15: 1 | W15: 1 | X15: 1 | Y15: 2 | Z15: 4 | AA15: 0
B16: Total Training Hours - previous year | C16: 120 | E16: Advanced Project Management Skills | F16: 30 | G16: =COUNTIF($G$40:$G$185,E16) -> 5 | H16: 7000 | I16: 2015 | J16: =COUNTIFS($L$40:$L$185,$J$3,$G$40:$G$185,E16) -> 0 | K16: =COUNTIFS($L$40:$L$185,$K$3,$G$40:$G$185,E16) -> 1 | L16: =COUNTIFS($L$40:$L$185,$L$3,$G$40:$G$185,E16) -> 1 | M16: =COUNTIFS($L$40:$L$185,$M$3,$G$40:$G$185,E16) -> 3 | N16: =COUNTIFS($L$40:$L$185,$N$3,$G$40:$G$185,E16) -> 0 | O16: =COUNTIFS($L$40:$L$185,$O$3,$G$40:$G$185,E16) -> 0 | U16: Advanced Project Management Skills | V16: 0 | W16: 1 | X16: 1 | Y16: 3 | Z16: 0 | AA16: 0
B17: Total Participants - % change | C17: =IF(C3=2015,0, IF(C3=2016,($C$19-$C$18)/$C$19,0)) -> 0.84 | E17: Advanced People Management Techniques | F17: 20 | G17: =COUNTIF($G$40:$G$185,E17) -> 5 | H17: 6000 | I17: 2015 | J17: =COUNTIFS($L$40:$L$185,$J$3,$G$40:$G$185,E17) -> 2 | K17: =COUNTIFS($L$40:$L$185,$K$3,$G$40:$G$185,E17) -> 1 | L17: =COUNTIFS($L$40:$L$185,$L$3,$G$40:$G$185,E17) -> 1 | M17: =COUNTIFS($L$40:$L$185,$M$3,$G$40:$G$185,E17) -> 0 | N17: =COUNTIFS($L$40:$L$185,$N$3,$G$40:$G$185,E17) -> 1 | O17: =COUNTIFS($L$40:$L$185,$O$3,$G$40:$G$185,E17) -> 0 | U17: Advanced People Management Techniques | V17: 2 | W17: 1 | X17: 1 | Y17: 0 | Z17: 1 | AA17: 0
B18: Total Participants - current year | C18: 20 | E18: Advanced People Management Skills | F18: 10 | G18: =COUNTIF($G$40:$G$185,E18) -> 7 | H18: 7000 | I18: 2015 | J18: =COUNTIFS($L$40:$L$185,$J$3,$G$40:$G$185,E18) -> 1 | K18: =COUNTIFS($L$40:$L$185,$K$3,$G$40:$G$185,E18) -> 0 | L18: =COUNTIFS($L$40:$L$185,$L$3,$G$40:$G$185,E18) -> 1 | M18: =COUNTIFS($L$40:$L$185,$M$3,$G$40:$G$185,E18) -> 3 | N18: =COUNTIFS($L$40:$L$185,$N$3,$G$40:$G$185,E18) -> 2 | O18: =COUNTIFS($L$40:$L$185,$O$3,$G$40:$G$185,E18) -> 0 | U18: Advanced People Management Skills | V18: 1 | W18: 0 | X18: 1 | Y18: 3 | Z18: 2 | AA18: 0
B19: Total Participants - previous year | C19: 125 | E19: Advanced People Management Methods | F19: 5 | G19: =COUNTIFS($G$40:$G$185,E19,$H$40:$H$185,$H$40) -> 7 | H19: 5000 | I19: 2015 | J19: =COUNTIFS($L$40:$L$185,$J$3,$G$40:$G$185,E19) -> 2 | K19: =COUNTIFS($L$40:$L$185,$K$3,$G$40:$G$185,E19) -> 2 | L19: =COUNTIFS($L$40:$L$185,$L$3,$G$40:$G$185,E19) -> 1 | M19: =COUNTIFS($L$40:$L$185,$M$3,$G$40:$G$185,E19) -> 1 | N19: =COUNTIFS($L$40:$L$185,$N$3,$G$40:$G$185,E19) -> 2 | O19: =COUNTIFS($L$40:$L$185,$O$3,$G$40:$G$185,E19) -> 0 | U19: Advanced People Management Methods | V19: 2 | W19: 2 | X19: 1 | Y19: 1 | Z19: 2 | AA19: 0
B20: Occupancy Rate - % change | C20: =IF(C3=2015,0, IF(C3=2016,($C$22-$C$21),0)) -> -0.0713 | E20: Advanced IT Techniques | F20: 30 | G20: =COUNTIF($G$40:$G$185,E20) -> 6 | H20: 5000 | I20: 2015 | J20: =COUNTIFS($L$40:$L$185,$J$3,$G$40:$G$185,E20) -> 0 | K20: =COUNTIFS($L$40:$L$185,$K$3,$G$40:$G$185,E20) -> 0 | L20: =COUNTIFS($L$40:$L$185,$L$3,$G$40:$G$185,E20) -> 0 | M20: =COUNTIFS($L$40:$L$185,$M$3,$G$40:$G$185,E20) -> 0 | N20: =COUNTIFS($L$40:$L$185,$N$3,$G$40:$G$185,E20) -> 0 | O20: =COUNTIFS($L$40:$L$185,$O$3,$G$40:$G$185,E20) -> 6 | U20: Advanced IT Techniques | V20: 0 | W20: 0 | X20: 0 | Y20: 0 | Z20: 0 | AA20: 6
B21: Occupancy Rate - current year | C21: 0.4444 | E21: Advanced IT Skills | F21: 15 | G21: =COUNTIF($G$40:$G$185,E21) -> 6 | H21: 3000 | I21: 2015 | J21: =COUNTIFS($L$40:$L$185,$J$3,$G$40:$G$185,E21) -> 0 | K21: =COUNTIFS($L$40:$L$185,$K$3,$G$40:$G$185,E21) -> 0 | L21: =COUNTIFS($L$40:$L$185,$L$3,$G$40:$G$185,E21) -> 0 | M21: =COUNTIFS($L$40:$L$185,$M$3,$G$40:$G$185,E21) -> 0 | N21: =COUNTIFS($L$40:$L$185,$N$3,$G$40:$G$185,E21) -> 0 | O21: =COUNTIFS($L$40:$L$185,$O$3,$G$40:$G$185,E21) -> 6 | U21: Advanced IT Skills | V21: 0 | W21: 0 | X21: 0 | Y21: 0 | Z21: 0 | AA21: 6
B22: Occupancy Rate - previous year | C22: 0.3731 | E22: Advanced Business Techniques | F22: 20 | G22: =COUNTIF($G$40:$G$185,E22) -> 1 | H22: 3000 | I22: 2015 | J22: =COUNTIFS($L$40:$L$185,$J$3,$G$40:$G$185,E22) -> 0 | K22: =COUNTIFS($L$40:$L$185,$K$3,$G$40:$G$185,E22) -> 0 | L22: =COUNTIFS($L$40:$L$185,$L$3,$G$40:$G$185,E22) -> 0 | M22: =COUNTIFS($L$40:$L$185,$M$3,$G$40:$G$185,E22) -> 0 | N22: =COUNTIFS($L$40:$L$185,$N$3,$G$40:$G$185,E22) -> 0 | O22: =COUNTIFS($L$40:$L$185,$O$3,$G$40:$G$185,E22) -> 1 | U22: Advanced Business Techniques | V22: 0 | W22: 0 | X22: 0 | Y22: 0 | Z22: 0 | AA22: 1
E23: Advanced Business Methods | F23: 30 | G23: =COUNTIF($G$40:$G$185,E23) -> 9 | H23: 3000 | I23: 2016 | J23: =COUNTIFS($L$40:$L$185,$J$3,$G$40:$G$185,E23) -> 0 | K23: =COUNTIFS($L$40:$L$185,$K$3,$G$40:$G$185,E23) -> 0 | L23: =COUNTIFS($L$40:$L$185,$L$3,$G$40:$G$185,E23) -> 0 | M23: =COUNTIFS($L$40:$L$185,$M$3,$G$40:$G$185,E23) -> 0 | N23: =COUNTIFS($L$40:$L$185,$N$3,$G$40:$G$185,E23) -> 0 | O23: =COUNTIFS($L$40:$L$185,$O$3,$G$40:$G$185,E23) -> 9 | U23: Advanced Business Methods | V23: 0 | W23: 0 | X23: 0 | Y23: 0 | Z23: 0 | AA23: 9
B24: Commentary | E24: Advanced Advertising Skills | F24: 15 | G24: =COUNTIF($G$40:$G$185,E24) -> 11 | H24: 6000 | I24: 2016 | J24: =COUNTIFS($L$40:$L$185,$J$3,$G$40:$G$185,E24) -> 0 | K24: =COUNTIFS($L$40:$L$185,$K$3,$G$40:$G$185,E24) -> 0 | L24: =COUNTIFS($L$40:$L$185,$L$3,$G$40:$G$185,E24) -> 0 | M24: =COUNTIFS($L$40:$L$185,$M$3,$G$40:$G$185,E24) -> 0 | N24: =COUNTIFS($L$40:$L$185,$N$3,$G$40:$G$185,E24) -> 0 | O24: =COUNTIFS($L$40:$L$185,$O$3,$G$40:$G$185,E24) -> 11 | U24: Advanced Advertising Skills | V24: 0 | W24: 0 | X24: 0 | Y24: 0 | Z24: 0 | AA24: 11
B25: As of FYE
B26: =$C$3 -> 2016
B27: , | G27: Course over capacity tagging is false
B28: the Total Training Hours is | G28: Exceeded
B29: =$C$7 -> 20
B30: , participated by
B31: =$C$8 -> 20 | C31: employees from different departments
B32: with
B33: =$C$10 -> 0.44444444
B34: Occupancy Rate. | C34: Accumulated cost is equal to | D34: =$C$5 -> 9000 | E34: .
B36: =CONCATENATE(B25,B26,B27,B28,B29,B30,B31,C31,B32,TEXT(B33,"0.00%"),B34,C34,TEXT(D34,"#,#"),E34) -> As of FYE 2016, the Total Training Hours is 20, participated by 20 employees from different departments with 44.44% Occupancy Rate. Accumulated cost is equal to 9,000.
B38: EMP LIST | F38: EMP TRAINING TRACKER | O38: TRAINING LIST
B39: ID | D39: Department | F39: Person Name | G39: Program Name | H39: Status | I39: DEPARTMENT | J39: DURATION | K39: TRAINING DATE | L39: Feedback Rating | O39: ID | P39: Program name | Q39: Trainer | R39: Date | S39: Year Only | T39: Duration | U39: Capacity | V39: Cost
B40: P0001 | C40: Abel Sherman | D40: Finance | F40: Abel Sherman | G40: Advanced People Management Techniques | H40: Nominated | I40: =IF(F40=$C$40,$D$40, IF(F40=$C$41,$D$41, IF(F40=$C$42,$D$42, IF(F40=$C$43,$D$43, IF(F40=$C$44,$D$44, IF(F40=$C$45,$D$45, IF(F40=$C$46,$D$46, IF(F40=$C$47,$D$47, IF(F40=$C$48,$D$48, IF(F40=$C$49,$D$49, IF(F40=$C$50,$D$50, IF(F40=$C$51,$D$51, IF(F40=$C$52,$D$52, IF(F40=$C$53,$D$53, IF(F40=$C$54,$D$54, IF(F40=$C$55,$D$55, IF(F40=$C$56,$D$56, IF(F40=$C$57,$D$57, IF(F40=$C$58,$D$58, IF(F40=$C$59,$D$59, IF(F40=$C$60,$D$60, IF(F40=$C$61,$D$61, IF(F40=$C$62,$D$62, IF(F40=$C$63,$D$63, IF(F40=$C$64,$D$64, IF(F40=$C$65,$D$65, IF(F40=$C$66,$D$66, IF(F40=$C$67,$D$67, IF(F40=$C$68,$D$68, IF(F40=$C$69,$D$69, IF(F40=$C$70,$D$70, IF(F40=$C$71,$D$71, IF(F40=$C$72,$D$72, IF(F40=$C$73,$D$73, IF(F40=$C$74,$D$74, IF(F40=$C$75,$D$75, IF(F40=$C$76,$D$76, IF(F40=$C$77,$D$77, IF(F40=$C$78,$D$78, IF(F40=$C$79,$D$79, IF(F40=$C$80,$D$80, IF(F40=$C$81,$D$81, IF(F40=$C$82,$D$82, IF(F40=$C$83,$D$83, IF(F40=$C$84,$D$84, IF(F40=$C$85,$D$85, IF(F40=$C$86,$D$86, IF(F40=$C$87,$D$87, IF(F40=$C$88,$D$88, IF(F40=$C$89,$D$89, IF(F40=$C$90,$D$90, IF(F40=$C$91,$D$91, IF(F40=$C$92,$D$92, IF(F40=$C$93,$D$93, IF(F40=$C$94,$D$94, IF(F40=$C$95,$D$95, IF(F40=$C$96,$D$96, IF(F40=$C$97,$D$97, IF(F40=$C$98,$D$98, IF(F40=$C$99,$D$99, IF(F40=C100,D100, IF(F40=C101,D101, IF(F40=C102,D102, IF(F40=C103,D103, IF(F40=C104,D104, "No Department"))))))))))))))))))))))))))))))))))))))))))))))))))))))))))))))))) -> Finance | J40: =IF(G40=$P$40,$T$40, IF(G40=$P$41,$T$41, IF(G40=$P$42,$T$42, IF(G40=$P$43,$T$43, IF(G40=$P$44,$T$44, IF(G40=$P$45,$T$45, IF(G40=$P$46,$T$46, IF(G40=$P$47,$T$47, IF(G40=$P$48,$T$48, IF(G40=$P$49,$T$49, IF(G40=$P$50,$T$50, IF(G40=$P$51,$T$51, IF(G40=$P$52,$T$52, IF(G40=$P$53,$T$53, IF(G40=$P$54,$T$54, IF(G40=$P$55,$T$55, IF(G40=$P$56,$T$56, IF(G40=$P$57,$T$57, IF(G40=$P$58,$T$58, IF(G40=$P$59,$T$59, IF(G40=$P$60,$T$60, "no info"))))))))))))))))))))) -> 1 | K40: =IF((OR($P$40=G40,$P$41=G40,$P$42=G40,$P$43=G40,$P$44=G40,$P$45=G40,$P$46=G40,$P$47=G40,$P$48=G40,$P$49=G40,$P$50=G40,$P$51=G40,$P$52=G40,$P$53=G40,$P$54=G40,$P$55=G40,$P$56=G40,$P$57=G40,$P$58=G40)),$S$40,"2016") -> 2015 | L40: 2 - Not happy | O40: T001 | P40: Basic Sales Skills | Q40: Eu Dolor Egestas Inc. | R40: 42009 | S40: =TEXT(R40,"yyyy") -> 2015 | T40: 1 | U40: 10 | V40: 5000
B41: P0002 | C41: Ahmed Cortez | D41: Marketing | F41: Abel Sherman | G41: Basic IT Methods | H41: Nominated | I41: =IF(F41=$C$40,$D$40, IF(F41=$C$41,$D$41, IF(F41=$C$42,$D$42, IF(F41=$C$43,$D$43, IF(F41=$C$44,$D$44, IF(F41=$C$45,$D$45, IF(F41=$C$46,$D$46, IF(F41=$C$47,$D$47, IF(F41=$C$48,$D$48, IF(F41=$C$49,$D$49, IF(F41=$C$50,$D$50, IF(F41=$C$51,$D$51, IF(F41=$C$52,$D$52, IF(F41=$C$53,$D$53, IF(F41=$C$54,$D$54, IF(F41=$C$55,$D$55, IF(F41=$C$56,$D$56, IF(F41=$C$57,$D$57, IF(F41=$C$58,$D$58, IF(F41=$C$59,$D$59, IF(F41=$C$60,$D$60, IF(F41=$C$61,$D$61, IF(F41=$C$62,$D$62, IF(F41=$C$63,$D$63, IF(F41=$C$64,$D$64, IF(F41=$C$65,$D$65, IF(F41=$C$66,$D$66, IF(F41=$C$67,$D$67, IF(F41=$C$68,$D$68, IF(F41=$C$69,$D$69, IF(F41=$C$70,$D$70, IF(F41=$C$71,$D$71, IF(F41=$C$72,$D$72, IF(F41=$C$73,$D$73, IF(F41=$C$74,$D$74, IF(F41=$C$75,$D$75, IF(F41=$C$76,$D$76, IF(F41=$C$77,$D$77, IF(F41=$C$78,$D$78, IF(F41=$C$79,$D$79, IF(F41=$C$80,$D$80, IF(F41=$C$81,$D$81, IF(F41=$C$82,$D$82, IF(F41=$C$83,$D$83, IF(F41=$C$84,$D$84, IF(F41=$C$85,$D$85, IF(F41=$C$86,$D$86, IF(F41=$C$87,$D$87, IF(F41=$C$88,$D$88, IF(F41=$C$89,$D$89, IF(F41=$C$90,$D$90, IF(F41=$C$91,$D$91, IF(F41=$C$92,$D$92, IF(F41=$C$93,$D$93, IF(F41=$C$94,$D$94, IF(F41=$C$95,$D$95, IF(F41=$C$96,$D$96, IF(F41=$C$97,$D$97, IF(F41=$C$98,$D$98, IF(F41=$C$99,$D$99, "No Department")))))))))))))))))))))))))))))))))))))))))))))))))))))))))))) -> Finance | J41: =IF(G41=$P$40,$T$40, IF(G41=$P$41,$T$41, IF(G41=$P$42,$T$42, IF(G41=$P$43,$T$43, IF(G41=$P$44,$T$44, IF(G41=$P$45,$T$45, IF(G41=$P$46,$T$46, IF(G41=$P$47,$T$47, IF(G41=$P$48,$T$48, IF(G41=$P$49,$T$49, IF(G41=$P$50,$T$50, IF(G41=$P$51,$T$51, IF(G41=$P$52,$T$52, IF(G41=$P$53,$T$53, IF(G41=$P$54,$T$54, IF(G41=$P$55,$T$55, IF(G41=$P$56,$T$56, IF(G41=$P$57,$T$57, IF(G41=$P$58,$T$58, IF(G41=$P$59,$T$59, IF(G41=$P$60,$T$60, "no info"))))))))))))))))))))) -> 1 | K41: =IF((OR($P$40=G41,$P$41=G41,$P$42=G41,$P$43=G41,$P$44=G41,$P$45=G41,$P$46=G41,$P$47=G41,$P$48=G41,$P$49=G41,$P$50=G41,$P$51=G41,$P$52=G41,$P$53=G41,$P$54=G41,$P$55=G41,$P$56=G41,$P$57=G41,$P$58=G41)),$S$40,"2016") -> 2015 | L41: 3 - Average | O41: T002 | P41: Basic Project Management Methods | Q41: Morbi Tristique Industries | R41: 42023 | S41: =TEXT(R41,"yyyy") -> 2015 | T41: 1 | U41: 5 | V41: 4000
B42: P0003 | C42: Ali Hernandez | D42: Sales | F42: Abel Sherman | G42: Basic People Management Methods | H42: Nominated | I42: =IF(F42=$C$40,$D$40, IF(F42=$C$41,$D$41, IF(F42=$C$42,$D$42, IF(F42=$C$43,$D$43, IF(F42=$C$44,$D$44, IF(F42=$C$45,$D$45, IF(F42=$C$46,$D$46, IF(F42=$C$47,$D$47, IF(F42=$C$48,$D$48, IF(F42=$C$49,$D$49, IF(F42=$C$50,$D$50, IF(F42=$C$51,$D$51, IF(F42=$C$52,$D$52, IF(F42=$C$53,$D$53, IF(F42=$C$54,$D$54, IF(F42=$C$55,$D$55, IF(F42=$C$56,$D$56, IF(F42=$C$57,$D$57, IF(F42=$C$58,$D$58, IF(F42=$C$59,$D$59, IF(F42=$C$60,$D$60, IF(F42=$C$61,$D$61, IF(F42=$C$62,$D$62, IF(F42=$C$63,$D$63, IF(F42=$C$64,$D$64, IF(F42=$C$65,$D$65, IF(F42=$C$66,$D$66, IF(F42=$C$67,$D$67, IF(F42=$C$68,$D$68, IF(F42=$C$69,$D$69, IF(F42=$C$70,$D$70, IF(F42=$C$71,$D$71, IF(F42=$C$72,$D$72, IF(F42=$C$73,$D$73, IF(F42=$C$74,$D$74, IF(F42=$C$75,$D$75, IF(F42=$C$76,$D$76, IF(F42=$C$77,$D$77, IF(F42=$C$78,$D$78, IF(F42=$C$79,$D$79, IF(F42=$C$80,$D$80, IF(F42=$C$81,$D$81, IF(F42=$C$82,$D$82, IF(F42=$C$83,$D$83, IF(F42=$C$84,$D$84, IF(F42=$C$85,$D$85, IF(F42=$C$86,$D$86, IF(F42=$C$87,$D$87, IF(F42=$C$88,$D$88, IF(F42=$C$89,$D$89, IF(F42=$C$90,$D$90, IF(F42=$C$91,$D$91, IF(F42=$C$92,$D$92, IF(F42=$C$93,$D$93, IF(F42=$C$94,$D$94, IF(F42=$C$95,$D$95, IF(F42=$C$96,$D$96, IF(F42=$C$97,$D$97, IF(F42=$C$98,$D$98, IF(F42=$C$99,$D$99, "No Department")))))))))))))))))))))))))))))))))))))))))))))))))))))))))))) -> Finance | J42: =IF(G42=$P$40,$T$40, IF(G42=$P$41,$T$41, IF(G42=$P$42,$T$42, IF(G42=$P$43,$T$43, IF(G42=$P$44,$T$44, IF(G42=$P$45,$T$45, IF(G42=$P$46,$T$46, IF(G42=$P$47,$T$47, IF(G42=$P$48,$T$48, IF(G42=$P$49,$T$49, IF(G42=$P$50,$T$50, IF(G42=$P$51,$T$51, IF(G42=$P$52,$T$52, IF(G42=$P$53,$T$53, IF(G42=$P$54,$T$54, IF(G42=$P$55,$T$55, IF(G42=$P$56,$T$56, IF(G42=$P$57,$T$57, IF(G42=$P$58,$T$58, IF(G42=$P$59,$T$59, IF(G42=$P$60,$T$60, "no info"))))))))))))))))))))) -> 1 | K42: =IF((OR($P$40=G42,$P$41=G42,$P$42=G42,$P$43=G42,$P$44=G42,$P$45=G42,$P$46=G42,$P$47=G42,$P$48=G42,$P$49=G42,$P$50=G42,$P$51=G42,$P$52=G42,$P$53=G42,$P$54=G42,$P$55=G42,$P$56=G42,$P$57=G42,$P$58=G42)),$S$40,"2016") -> 2015 | L42: 4 - Happy | O42: T003 | P42: Basic People Management Techniques | Q42: Interdum Company | R42: 42034 | S42: =TEXT(R42,"yyyy") -> 2015 | T42: 1 | U42: 30 | V42: 2000
...

Sheet Linked Charts
A2: Participants by Department vs Sum of Training Hours
C3: Finance | D3: HR | E3: IT | F3: Marketing | G3: Operations | H3: Sales
A4: =Dashboard!$E$6 -> 2016 | B4: Participants | C4: =COUNTIFS(Calculations!$I$40:$I$185,'Linked Charts'!$C$3,Calculations!$K$40:$K$185,'Linked Charts'!$A$4) -> 7 | D4: =COUNTIFS(Calculations!$I$40:$I$185,'Linked Charts'!$D$3,Calculations!$K$40:$K$185,'Linked Charts'!$A$4) -> 2 | E4: =COUNTIFS(Calculations!$I$40:$I$185,'Linked Charts'!$E$3,Calculations!$K$40:$K$185,'Linked Charts'!$A$4) -> 0 | F4: =COUNTIFS(Calculations!$I$40:$I$185,'Linked Charts'!$F$3,Calculations!$K$40:$K$185,'Linked Charts'!$A$4) -> 3 | G4: =COUNTIFS(Calculations!$I$40:$I$185,'Linked Charts'!$G$3,Calculations!$K$40:$K$185,'Linked Charts'!$A$4) -> 5 | H4: =COUNTIFS(Calculations!$I$40:$I$185,'Linked Charts'!$H$3,Calculations!$K$40:$K$185,'Linked Charts'!$A$4) -> 3
A5: =Dashboard!$E$6 -> 2016 | B5: Training Hours | C5: =SUMIFS(Calculations!$J$40:$J$185,Calculations!$I$40:$I$185,'Linked Charts'!$C$3,Calculations!$K$40:$K$185,'Linked Charts'!$A$5) -> 7 | D5: =SUMIFS(Calculations!$J$40:$J$185,Calculations!$I$40:$I$185,'Linked Charts'!$D$3,Calculations!$K$40:$K$185,'Linked Charts'!$A$5) -> 2 | E5: =SUMIFS(Calculations!$J$40:$J$185,Calculations!$I$40:$I$185,'Linked Charts'!$E$3,Calculations!$K$40:$K$185,'Linked Charts'!$A$5) -> 0 | F5: =SUMIFS(Calculations!$J$40:$J$185,Calculations!$I$40:$I$185,'Linked Charts'!$F$3,Calculations!$K$40:$K$185,'Linked Charts'!$A$5) -> 3 | G5: =SUMIFS(Calculations!$J$40:$J$185,Calculations!$I$40:$I$185,'Linked Charts'!$G$3,Calculations!$K$40:$K$185,'Linked Charts'!$A$5) -> 5 | H5: =SUMIFS(Calculations!$J$40:$J$185,Calculations!$I$40:$I$185,'Linked Charts'!$H$3,Calculations!$K$40:$K$185,'Linked Charts'!$A$5) -> 3
A9: Training Capacity vs Actual Number of Participants
A11: =Dashboard!$E$6 -> 2016 | B11: Training Name | C11: Training Capacity | D11: Actual Number of Participants (Employee per Program)
B12: Basic Sales Skills | C12: 10 | D12: =COUNTIFS(Calculations!$G$40:$G$185,'Linked Charts'!B12,Calculations!$K$40:$K$185,'Linked Charts'!$A$11) -> 0
B13: Basic Project Management Methods | C13: 5 | D13: =COUNTIFS(Calculations!$G$40:$G$185,'Linked Charts'!B13,Calculations!$K$40:$K$185,'Linked Charts'!$A$11) -> 0
B14: Basic People Management Techniques | C14: 30 | D14: =COUNTIFS(Calculations!$G$40:$G$185,'Linked Charts'!B14,Calculations!$K$40:$K$185,'Linked Charts'!$A$11) -> 0
B15: Basic People Management Skills | C15: 25 | D15: =COUNTIFS(Calculations!$G$40:$G$185,'Linked Charts'!B15,Calculations!$K$40:$K$185,'Linked Charts'!$A$11) -> 0
B16: Basic People Management Methods | C16: 20 | D16: =COUNTIFS(Calculations!$G$40:$G$185,'Linked Charts'!B16,Calculations!$K$40:$K$185,'Linked Charts'!$A$11) -> 0
B17: Basic IT Methods | C17: 5 | D17: =COUNTIFS(Calculations!$G$40:$G$185,'Linked Charts'!B17,Calculations!$K$40:$K$185,'Linked Charts'!$A$11) -> 0
B18: Basic Business Skills | C18: 25 | D18: =COUNTIFS(Calculations!$G$40:$G$185,'Linked Charts'!B18,Calculations!$K$40:$K$185,'Linked Charts'!$A$11) -> 0
B19: Basic Advertising Techniques | C19: 15 | D19: =COUNTIFS(Calculations!$G$40:$G$185,'Linked Charts'!B19,Calculations!$K$40:$K$185,'Linked Charts'!$A$11) -> 0
B20: Basic Advertising Skills | C20: 15 | D20: =COUNTIFS(Calculations!$G$40:$G$185,'Linked Charts'!B20,Calculations!$K$40:$K$185,'Linked Charts'!$A$11) -> 0
B21: Basic Advertising Methods | C21: 5 | D21: =COUNTIFS(Calculations!$G$40:$G$185,'Linked Charts'!B21,Calculations!$K$40:$K$185,'Linked Charts'!$A$11) -> 0
B22: Advanced Sales Techniques | C22: 20 | D22: =COUNTIFS(Calculations!$G$40:$G$185,'Linked Charts'!B22,Calculations!$K$40:$K$185,'Linked Charts'!$A$11) -> 0
B23: Advanced Sales Methods | C23: 30 | D23: =COUNTIFS(Calculations!$G$40:$G$185,'Linked Charts'!B23,Calculations!$K$40:$K$185,'Linked Charts'!$A$11) -> 0
... B32: Advanced Advertising Skills | C32: 15 | D32: =COUNTIFS(Calculations!$G$40:$G$185,'Linked Charts'!B32,Calculations!$K$40:$K$185,'Linked Charts'!$A$11) -> 11
A35: Ratings
A37: =Dashboard!$E$6 -> 2016 | B37: Training Name | C37: 1 - Disaster | D37: 2 - Not happy | E37: 3 - Average | F37: 4 - Happy | G37: 5 - Very happy | H37: Unrated
B39: Basic Sales Skills | C39: =COUNTIFS(Calculations!$G$40:$G$185,'Linked Charts'!B39,Calculations!$L$40:$L$185,'Linked Charts'!$C$37,Calculations!$K$40:$K$185,'Linked Charts'!$A$37) -> 0 | D39: =COUNTIFS(Calculations!$G$40:$G$185,'Linked Charts'!B39,Calculations!$L$40:$L$185,'Linked Charts'!$D$37,Calculations!$K$40:$K$185,'Linked Charts'!$A$37) -> 0 | E39: =COUNTIFS(Calculations!$G$40:$G$185,'Linked Charts'!B39,Calculations!$L$40:$L$185,'Linked Charts'!$E$37,Calculations!$K$40:$K$185,'Linked Charts'!$A$37) -> 0 | F39: =COUNTIFS(Calculations!$G$40:$G$185,'Linked Charts'!B39,Calculations!$L$40:$L$185,'Linked Charts'!$F$37,Calculations!$K$40:$K$185,'Linked Charts'!$A$37) -> 0 | G39: =COUNTIFS(Calculations!$G$40:$G$185,'Linked Charts'!B39,Calculations!$L$40:$L$185,'Linked Charts'!$G$37,Calculations!$K$40:$K$185,'Linked Charts'!$A$37) -> 0 | H39: =COUNTIFS(Calculations!$G$40:$G$185,'Linked Charts'!B39,Calculations!$L$40:$L$185,'Linked Charts'!$H$37,Calculations!$K$40:$K$185,'Linked Charts'!$A$37) -> 0
B40: Basic Project Management Methods | C40: =COUNTIFS(Calculations!$G$40:$G$185,'Linked Charts'!B40,Calculations!$L$40:$L$185,'Linked Charts'!$C$37,Calculations!$K$40:$K$185,'Linked Charts'!$A$37) -> 0 | D40: =COUNTIFS(Calculations!$G$40:$G$185,'Linked Charts'!B40,Calculations!$L$40:$L$185,'Linked Charts'!$D$37,Calculations!$K$40:$K$185,'Linked Charts'!$A$37) -> 0 | E40: =COUNTIFS(Calculations!$G$40:$G$185,'Linked Charts'!B40,Calculations!$L$40:$L$185,'Linked Charts'!$E$37,Calculations!$K$40:$K$185,'Linked Charts'!$A$37) -> 0 | F40: =COUNTIFS(Calculations!$G$40:$G$185,'Linked Charts'!B40,Calculations!$L$40:$L$185,'Linked Charts'!$F$37,Calculations!$K$40:$K$185,'Linked Charts'!$A$37) -> 0 | G40: =COUNTIFS(Calculations!$G$40:$G$185,'Linked Charts'!B40,Calculations!$L$40:$L$185,'Linked Charts'!$G$37,Calculations!$K$40:$K$185,'Linked Charts'!$A$37) -> 0 | H40: =COUNTIFS(Calculations!$G$40:$G$185,'Linked Charts'!B40,Calculations!$L$40:$L$185,'Linked Charts'!$H$37,Calculations!$K$40:$K$185,'Linked Charts'!$A$37) -> 0
B41: Basic People Management Techniques | C41: =COUNTIFS(Calculations!$G$40:$G$185,'Linked Charts'!B41,Calculations!$L$40:$L$185,'Linked Charts'!$C$37,Calculations!$K$40:$K$185,'Linked Charts'!$A$37) -> 0 | D41: =COUNTIFS(Calculations!$G$40:$G$185,'Linked Charts'!B41,Calculations!$L$40:$L$185,'Linked Charts'!$D$37,Calculations!$K$40:$K$185,'Linked Charts'!$A$37) -> 0 | E41: =COUNTIFS(Calculations!$G$40:$G$185,'Linked Charts'!B41,Calculations!$L$40:$L$185,'Linked Charts'!$E$37,Calculations!$K$40:$K$185,'Linked Charts'!$A$37) -> 0 | F41: =COUNTIFS(Calculations!$G$40:$G$185,'Linked Charts'!B41,Calculations!$L$40:$L$185,'Linked Charts'!$F$37,Calculations!$K$40:$K$185,'Linked Charts'!$A$37) -> 0 | G41: =COUNTIFS(Calculations!$G$40:$G$185,'Linked Charts'!B41,Calculations!$L$40:$L$185,'Linked Charts'!$G$37,Calculations!$K$40:$K$185,'Linked Charts'!$A$37) -> 0 | H41: =COUNTIFS(Calculations!$G$40:$G$185,'Linked Charts'!B41,Calculations!$L$40:$L$185,'Linked Charts'!$H$37,Calculations!$K$40:$K$185,'Linked Charts'!$A$37) -> 0
B42: Basic People Management Skills | C42: =COUNTIFS(Calculations!$G$40:$G$185,'Linked Charts'!B42,Calculations!$L$40:$L$185,'Linked Charts'!$C$37,Calculations!$K$40:$K$185,'Linked Charts'!$A$37) -> 0 | D42: =COUNTIFS(Calculations!$G$40:$G$185,'Linked Charts'!B42,Calculations!$L$40:$L$185,'Linked Charts'!$D$37,Calculations!$K$40:$K$185,'Linked Charts'!$A$37) -> 0 | E42: =COUNTIFS(Calculations!$G$40:$G$185,'Linked Charts'!B42,Calculations!$L$40:$L$185,'Linked Charts'!$E$37,Calculations!$K$40:$K$185,'Linked Charts'!$A$37) -> 0 | F42: =COUNTIFS(Calculations!$G$40:$G$185,'Linked Charts'!B42,Calculations!$L$40:$L$185,'Linked Charts'!$F$37,Calculations!$K$40:$K$185,'Linked Charts'!$A$37) -> 0 | G42: =COUNTIFS(Calculations!$G$40:$G$185,'Linked Charts'!B42,Calculations!$L$40:$L$185,'Linked Charts'!$G$37,Calculations!$K$40:$K$185,'Linked Charts'!$A$37) -> 0 | H42: =COUNTIFS(Calculations!$G$40:$G$185,'Linked Charts'!B42,Calculations!$L$40:$L$185,'Linked Charts'!$H$37,Calculations!$K$40:$K$185,'Linked Charts'!$A$37) -> 0
B43: Basic People Management Methods | C43: =COUNTIFS(Calculations!$G$40:$G$185,'Linked Charts'!B43,Calculations!$L$40:$L$185,'Linked Charts'!$C$37,Calculations!$K$40:$K$185,'Linked Charts'!$A$37) -> 0 | D43: =COUNTIFS(Calculations!$G$40:$G$185,'Linked Charts'!B43,Calculations!$L$40:$L$185,'Linked Charts'!$D$37,Calculations!$K$40:$K$185,'Linked Charts'!$A$37) -> 0 | E43: =COUNTIFS(Calculations!$G$40:$G$185,'Linked Charts'!B43,Calculations!$L$40:$L$185,'Linked Charts'!$E$37,Calculations!$K$40:$K$185,'Linked Charts'!$A$37) -> 0 | F43: =COUNTIFS(Calculations!$G$40:$G$185,'Linked Charts'!B43,Calculations!$L$40:$L$185,'Linked Charts'!$F$37,Calculations!$K$40:$K$185,'Linked Charts'!$A$37) -> 0 | G43: =COUNTIFS(Calculations!$G$40:$G$185,'Linked Charts'!B43,Calculations!$L$40:$L$185,'Linked Charts'!$G$37,Calculations!$K$40:$K$185,'Linked Charts'!$A$37) -> 0 | H43: =COUNTIFS(Calculations!$G$40:$G$185,'Linked Charts'!B43,Calculations!$L$40:$L$185,'Linked Charts'!$H$37,Calculations!$K$40:$K$185,'Linked Charts'!$A$37) -> 0
B44: Basic IT Methods | C44: =COUNTIFS(Calculations!$G$40:$G$185,'Linked Charts'!B44,Calculations!$L$40:$L$185,'Linked Charts'!$C$37,Calculations!$K$40:$K$185,'Linked Charts'!$A$37) -> 0 | D44: =COUNTIFS(Calculations!$G$40:$G$185,'Linked Charts'!B44,Calculations!$L$40:$L$185,'Linked Charts'!$D$37,Calculations!$K$40:$K$185,'Linked Charts'!$A$37) -> 0 | E44: =COUNTIFS(Calculations!$G$40:$G$185,'Linked Charts'!B44,Calculations!$L$40:$L$185,'Linked Charts'!$E$37,Calculations!$K$40:$K$185,'Linked Charts'!$A$37) -> 0 | F44: =COUNTIFS(Calculations!$G$40:$G$185,'Linked Charts'!B44,Calculations!$L$40:$L$185,'Linked Charts'!$F$37,Calculations!$K$40:$K$185,'Linked Charts'!$A$37) -> 0 | G44: =COUNTIFS(Calculations!$G$40:$G$185,'Linked Charts'!B44,Calculations!$L$40:$L$185,'Linked Charts'!$G$37,Calculations!$K$40:$K$185,'Linked Charts'!$A$37) -> 0 | H44: =COUNTIFS(Calculations!$G$40:$G$185,'Linked Charts'!B44,Calculations!$L$40:$L$185,'Linked Charts'!$H$37,Calculations!$K$40:$K$185,'Linked Charts'!$A$37) -> 0
B45: Basic Business Skills | C45: =COUNTIFS(Calculations!$G$40:$G$185,'Linked Charts'!B45,Calculations!$L$40:$L$185,'Linked Charts'!$C$37,Calculations!$K$40:$K$185,'Linked Charts'!$A$37) -> 0 | D45: =COUNTIFS(Calculations!$G$40:$G$185,'Linked Charts'!B45,Calculations!$L$40:$L$185,'Linked Charts'!$D$37,Calculations!$K$40:$K$185,'Linked Charts'!$A$37) -> 0 | E45: =COUNTIFS(Calculations!$G$40:$G$185,'Linked Charts'!B45,Calculations!$L$40:$L$185,'Linked Charts'!$E$37,Calculations!$K$40:$K$185,'Linked Charts'!$A$37) -> 0 | F45: =COUNTIFS(Calculations!$G$40:$G$185,'Linked Charts'!B45,Calculations!$L$40:$L$185,'Linked Charts'!$F$37,Calculations!$K$40:$K$185,'Linked Charts'!$A$37) -> 0 | G45: =COUNTIFS(Calculations!$G$40:$G$185,'Linked Charts'!B45,Calculations!$L$40:$L$185,'Linked Charts'!$G$37,Calculations!$K$40:$K$185,'Linked Charts'!$A$37) -> 0 | H45: =COUNTIFS(Calculations!$G$40:$G$185,'Linked Charts'!B45,Calculations!$L$40:$L$185,'Linked Charts'!$H$37,Calculations!$K$40:$K$185,'Linked Charts'!$A$37) -> 0
B46: Basic Advertising Techniques | C46: =COUNTIFS(Calculations!$G$40:$G$185,'Linked Charts'!B46,Calculations!$L$40:$L$185,'Linked Charts'!$C$37,Calculations!$K$40:$K$185,'Linked Charts'!$A$37) -> 0 | D46: =COUNTIFS(Calculations!$G$40:$G$185,'Linked Charts'!B46,Calculations!$L$40:$L$185,'Linked Charts'!$D$37,Calculations!$K$40:$K$185,'Linked Charts'!$A$37) -> 0 | E46: =COUNTIFS(Calculations!$G$40:$G$185,'Linked Charts'!B46,Calculations!$L$40:$L$185,'Linked Charts'!$E$37,Calculations!$K$40:$K$185,'Linked Charts'!$A$37) -> 0 | F46: =COUNTIFS(Calculations!$G$40:$G$185,'Linked Charts'!B46,Calculations!$L$40:$L$185,'Linked Charts'!$F$37,Calculations!$K$40:$K$185,'Linked Charts'!$A$37) -> 0 | G46: =COUNTIFS(Calculations!$G$40:$G$185,'Linked Charts'!B46,Calculations!$L$40:$L$185,'Linked Charts'!$G$37,Calculations!$K$40:$K$185,'Linked Charts'!$A$37) -> 0 | H46: =COUNTIFS(Calculations!$G$40:$G$185,'Linked Charts'!B46,Calculations!$L$40:$L$185,'Linked Charts'!$H$37,Calculations!$K$40:$K$185,'Linked Charts'!$A$37) -> 0
B47: Basic Advertising Skills | C47: =COUNTIFS(Calculations!$G$40:$G$185,'Linked Charts'!B47,Calculations!$L$40:$L$185,'Linked Charts'!$C$37,Calculations!$K$40:$K$185,'Linked Charts'!$A$37) -> 0 | D47: =COUNTIFS(Calculations!$G$40:$G$185,'Linked Charts'!B47,Calculations!$L$40:$L$185,'Linked Charts'!$D$37,Calculations!$K$40:$K$185,'Linked Charts'!$A$37) -> 0 | E47: =COUNTIFS(Calculations!$G$40:$G$185,'Linked Charts'!B47,Calculations!$L$40:$L$185,'Linked Charts'!$E$37,Calculations!$K$40:$K$185,'Linked Charts'!$A$37) -> 0 | F47: =COUNTIFS(Calculations!$G$40:$G$185,'Linked Charts'!B47,Calculations!$L$40:$L$185,'Linked Charts'!$F$37,Calculations!$K$40:$K$185,'Linked Charts'!$A$37) -> 0 | G47: =COUNTIFS(Calculations!$G$40:$G$185,'Linked Charts'!B47,Calculations!$L$40:$L$185,'Linked Charts'!$G$37,Calculations!$K$40:$K$185,'Linked Charts'!$A$37) -> 0 | H47: =COUNTIFS(Calculations!$G$40:$G$185,'Linked Charts'!B47,Calculations!$L$40:$L$185,'Linked Charts'!$H$37,Calculations!$K$40:$K$185,'Linked Charts'!$A$37) -> 0
B48: Basic Advertising Methods | C48: =COUNTIFS(Calculations!$G$40:$G$185,'Linked Charts'!B48,Calculations!$L$40:$L$185,'Linked Charts'!$C$37,Calculations!$K$40:$K$185,'Linked Charts'!$A$37) -> 0 | D48: =COUNTIFS(Calculations!$G$40:$G$185,'Linked Charts'!B48,Calculations!$L$40:$L$185,'Linked Charts'!$D$37,Calculations!$K$40:$K$185,'Linked Charts'!$A$37) -> 0 | E48: =COUNTIFS(Calculations!$G$40:$G$185,'Linked Charts'!B48,Calculations!$L$40:$L$185,'Linked Charts'!$E$37,Calculations!$K$40:$K$185,'Linked Charts'!$A$37) -> 0 | F48: =COUNTIFS(Calculations!$G$40:$G$185,'Linked Charts'!B48,Calculations!$L$40:$L$185,'Linked Charts'!$F$37,Calculations!$K$40:$K$185,'Linked Charts'!$A$37) -> 0 | G48: =COUNTIFS(Calculations!$G$40:$G$185,'Linked Charts'!B48,Calculations!$L$40:$L$185,'Linked Charts'!$G$37,Calculations!$K$40:$K$185,'Linked Charts'!$A$37) -> 0 | H48: =COUNTIFS(Calculations!$G$40:$G$185,'Linked Charts'!B48,Calculations!$L$40:$L$185,'Linked Charts'!$H$37,Calculations!$K$40:$K$185,'Linked Charts'!$A$37) -> 0
B49: Advanced Sales Techniques | C49: =COUNTIFS(Calculations!$G$40:$G$185,'Linked Charts'!B49,Calculations!$L$40:$L$185,'Linked Charts'!$C$37,Calculations!$K$40:$K$185,'Linked Charts'!$A$37) -> 0 | D49: =COUNTIFS(Calculations!$G$40:$G$185,'Linked Charts'!B49,Calculations!$L$40:$L$185,'Linked Charts'!$D$37,Calculations!$K$40:$K$185,'Linked Charts'!$A$37) -> 0 | E49: =COUNTIFS(Calculations!$G$40:$G$185,'Linked Charts'!B49,Calculations!$L$40:$L$185,'Linked Charts'!$E$37,Calculations!$K$40:$K$185,'Linked Charts'!$A$37) -> 0 | F49: =COUNTIFS(Calculations!$G$40:$G$185,'Linked Charts'!B49,Calculations!$L$40:$L$185,'Linked Charts'!$F$37,Calculations!$K$40:$K$185,'Linked Charts'!$A$37) -> 0 | G49: =COUNTIFS(Calculations!$G$40:$G$185,'Linked Charts'!B49,Calculations!$L$40:$L$185,'Linked Charts'!$G$37,Calculations!$K$40:$K$185,'Linked Charts'!$A$37) -> 0 | H49: =COUNTIFS(Calculations!$G$40:$G$185,'Linked Charts'!B49,Calculations!$L$40:$L$185,'Linked Charts'!$H$37,Calculations!$K$40:$K$185,'Linked Charts'!$A$37) -> 0
B50: Advanced Sales Methods | C50: =COUNTIFS(Calculations!$G$40:$G$185,'Linked Charts'!B50,Calculations!$L$40:$L$185,'Linked Charts'!$C$37,Calculations!$K$40:$K$185,'Linked Charts'!$A$37) -> 0 | D50: =COUNTIFS(Calculations!$G$40:$G$185,'Linked Charts'!B50,Calculations!$L$40:$L$185,'Linked Charts'!$D$37,Calculations!$K$40:$K$185,'Linked Charts'!$A$37) -> 0 | E50: =COUNTIFS(Calculations!$G$40:$G$185,'Linked Charts'!B50,Calculations!$L$40:$L$185,'Linked Charts'!$E$37,Calculations!$K$40:$K$185,'Linked Charts'!$A$37) -> 0 | F50: =COUNTIFS(Calculations!$G$40:$G$185,'Linked Charts'!B50,Calculations!$L$40:$L$185,'Linked Charts'!$F$37,Calculations!$K$40:$K$185,'Linked Charts'!$A$37) -> 0 | G50: =COUNTIFS(Calculations!$G$40:$G$185,'Linked Charts'!B50,Calculations!$L$40:$L$185,'Linked Charts'!$G$37,Calculations!$K$40:$K$185,'Linked Charts'!$A$37) -> 0 | H50: =COUNTIFS(Calculations!$G$40:$G$185,'Linked Charts'!B50,Calculations!$L$40:$L$185,'Linked Charts'!$H$37,Calculations!$K$40:$K$185,'Linked Charts'!$A$37) -> 0
... B59: Advanced Advertising Skills | C59: =COUNTIFS(Calculations!$G$40:$G$185,'Linked Charts'!B59,Calculations!$L$40:$L$185,'Linked Charts'!$C$37,Calculations!$K$40:$K$185,'Linked Charts'!$A$37) -> 0 | D59: =COUNTIFS(Calculations!$G$40:$G$185,'Linked Charts'!B59,Calculations!$L$40:$L$185,'Linked Charts'!$D$37,Calculations!$K$40:$K$185,'Linked Charts'!$A$37) -> 0 | E59: =COUNTIFS(Calculations!$G$40:$G$185,'Linked Charts'!B59,Calculations!$L$40:$L$185,'Linked Charts'!$E$37,Calculations!$K$40:$K$185,'Linked Charts'!$A$37) -> 0 | F59: =COUNTIFS(Calculations!$G$40:$G$185,'Linked Charts'!B59,Calculations!$L$40:$L$185,'Linked Charts'!$F$37,Calculations!$K$40:$K$185,'Linked Charts'!$A$37) -> 0 | G59: =COUNTIFS(Calculations!$G$40:$G$185,'Linked Charts'!B59,Calculations!$L$40:$L$185,'Linked Charts'!$G$37,Calculations!$K$40:$K$185,'Linked Charts'!$A$37) -> 0 | H59: =COUNTIFS(Calculations!$G$40:$G$185,'Linked Charts'!B59,Calculations!$L$40:$L$185,'Linked Charts'!$H$37,Calculations!$K$40:$K$185,'Linked Charts'!$A$37) -> 11
A63: SMEs | B63: =Dashboard!$E$6 -> 2016
A64: Name of Company | B64: Program Count | C64: Training Name | D64: Average Ratings
A65: Eu Dolor Egestas Inc. | B65: =COUNTIFS(Calculations!$Q$40:$Q$60,'Linked Charts'!A65,Calculations!I$4:I$24,'Linked Charts'!$B$63) -> 0 | C65: Basic Sales Skills | D65: =AVERAGE(C39:H39) -> 0
A66: Morbi Tristique Industries | B66: =COUNTIFS(Calculations!$Q$40:$Q$60,'Linked Charts'!A66,Calculations!I$4:I$24,'Linked Charts'!$B$63) -> 1 | C66: Basic Project Management Methods | D66: =AVERAGE(C40:H40) -> 0
A67: Interdum Company | B67: =COUNTIFS(Calculations!$Q$40:$Q$60,'Linked Charts'!A67,Calculations!I$4:I$24,'Linked Charts'!$B$63) -> 1 | C67: Basic People Management Techniques | D67: =AVERAGE(C41:H41) -> 0
A68: Metus In Nec Foundation | B68: =COUNTIFS(Calculations!$Q$40:$Q$60,'Linked Charts'!A68,Calculations!I$4:I$24,'Linked Charts'!$B$63) -> 0 | C68: Basic People Management Skills | D68: =AVERAGE(C42:H42) -> 0
...

Sheet Dashboard
C6: Select Year | E6: 2016
C8: Total Training Hours | I8: Training Cost | O8: Total Participants | U8: Occupancy Rate
AC9: ANALYST NOTE:
C10: =Calculations!$C$7 -> 20 | I10: =Calculations!$C$5 -> 9000 | O10: =Calculations!$C$6 -> 20 | U10: =Calculations!$C$10 -> 0.44444444 | AC10: Due to insufficient data from previous and current year, the analyst decided to make a data selection based on the Year only as adding a separate selector like Department will make the dashboard less vibrant and appealing.
D19: =Calculations!$C$14 -> 0.83333333 | J19: =Calculations!$C$11 -> 0.74285714 | P19: =Calculations!$C$17 -> 0.84 | V19: =Calculations!$C$20 -> -0.0713
C20: vs. last period | I20: vs. last period | O20: vs. last period | U20: vs. last period
D63: =Calculations!$B$36 -> As of FYE 2016, the Total Training Hours is 20, participated by 20 employees from different departments with 44.44% Occupancy Rate. Accumulated cost is equal to 9,000.
